<sdf version='1.10'>
  <world name='default'>
    <gravity>0 0 -9.8000000000000007</gravity>
    <magnetic_field>5.5644999999999998e-06 2.2875799999999999e-05 -4.2388400000000002e-05</magnetic_field>
    <atmosphere type='adiabatic'/>
    <physics type='ode'>
      <max_step_size>0.001</max_step_size>
      <real_time_factor>1</real_time_factor>
      <real_time_update_rate>1000</real_time_update_rate>
    </physics>
    <scene>
      <ambient>0.400000006 0.400000006 0.400000006 1</ambient>
      <background>0.699999988 0.699999988 0.699999988 1</background>
      <shadows>true</shadows>
    </scene>
    <model name='sandy_terrain'>
      <static>true</static>
      <link name='sand_surface'>
        <collision name='collision'>
          <geometry>
            <mesh>
              <uri>file:///home/turtle_on_land/gazebo_worlds/SANDY_TERRAINII.dae</uri>
            </mesh>
          </geometry>
          <surface>
            <friction>
              <ode>
                <mu>0.40000000000000002</mu>
                <mu2>0.40000000000000002</mu2>
                <slip1>0.20000000000000001</slip1>
                <slip2>0.20000000000000001</slip2>
              </ode>
              <torsional>
                <coefficient>0.02</coefficient>
                <use_patch_radius>true</use_patch_radius>
                <patch_radius>0.050000000000000003</patch_radius>
                <surface_radius>0.050000000000000003</surface_radius>
                <ode>
                  <slip>0.01</slip>
                </ode>
              </torsional>
            </friction>
            <bounce>
              <restitution_coefficient>0.050000000000000003</restitution_coefficient>
              <threshold>100</threshold>
            </bounce>
            <contact>
              <ode>
                <soft_cfm>0.10000000000000001</soft_cfm>
                <soft_erp>0.10000000000000001</soft_erp>
                <kp>500</kp>
                <kd>5</kd>
                <max_vel>0.10000000000000001</max_vel>
                <min_depth>0.01</min_depth>
              </ode>
            </contact>
          </surface>
        </collision>
        <visual name='visual'>
          <geometry>
            <mesh>
              <uri>file:///home/turtle_on_land/gazebo_worlds/SANDY_TERRAINII.dae</uri>
            </mesh>
          </geometry>
        </visual>
        <pose>0 0 0 0 0 0</pose>
        <inertial>
          <pose>0 0 0 0 0 0</pose>
          <mass>1</mass>
          <inertia>
            <ixx>1</ixx>
            <ixy>0</ixy>
            <ixz>0</ixz>
            <iyy>1</iyy>
            <iyz>0</iyz>
            <izz>1</izz>
          </inertia>
        </inertial>
        <enable_wind>false</enable_wind>
      </link>
      <pose>0 0 0 0 0 0</pose>
      <self_collide>false</self_collide>
    </model>
    <model name='test_sphere'>
      <static>false</static>
      <link name='link'>
        <inertial>
          <mass>1</mass>
          <pose>0 0 0 0 0 0</pose>
          <inertia>
            <ixx>1</ixx>
            <ixy>0</ixy>
            <ixz>0</ixz>
            <iyy>1</iyy>
            <iyz>0</iyz>
            <izz>1</izz>
          </inertia>
        </inertial>
        <collision name='collision'>
          <geometry>
            <sphere>
              <radius>0.10000000000000001</radius>
            </sphere>
          </geometry>
          <surface>
            <contact>
              <ode>
                <soft_cfm>0.050000000000000003</soft_cfm>
                <soft_erp>0.20000000000000001</soft_erp>
              </ode>
            </contact>
            <friction>
              <ode/>
            </friction>
            <bounce/>
          </surface>
        </collision>
        <visual name='visual'>
          <geometry>
            <sphere>
              <radius>0.10000000000000001</radius>
            </sphere>
          </geometry>
        </visual>
        <pose>0 0 1 0 0 0</pose>
        <enable_wind>false</enable_wind>
      </link>
      <pose>-0.21807787462375605 -0.048271984157666981 0.20516829978018342 -1.7182881460127526 0.6241334444689095 -0.99688965925541484</pose>
      <self_collide>false</self_collide>
    </model>
    <model name='robot1'>
      <link name='base_footprint'>
        <inertial>
          <pose>-0.0063662267801659544 -2.8575276448950229e-05 0.0022585393228131819 0 0 0</pose>
          <mass>1.0328729509133769</mass>
          <inertia>
            <ixx>0.0029425338401379269</ixx>
            <ixy>-3.898237266515236e-07</ixy>
            <ixz>-6.4472036763859103e-05</ixz>
            <iyy>0.0048023115586267326</iyy>
            <iyz>1.039913828623274e-07</iyz>
            <izz>0.0070326121241304478</izz>
          </inertia>
        </inertial>
        <collision name='base_footprint_fixed_joint_lump__base_link_collision'>
          <pose>0 0 0.001 0 0 0</pose>
          <geometry>
            <mesh>
              <scale>1 1 1</scale>
              <uri>file:///home/turtle_on_land/dev_ws/install/landTurtle2/share/landTurtle2/urdf/model://meshes/visual/base_link.STL</uri>
            </mesh>
          </geometry>
        </collision>
        <visual name='base_footprint_visual'>
          <pose>0 0 0 0 0 0</pose>
          <geometry>
            <box>
              <size>0.001 0.001 0.001</size>
            </box>
          </geometry>
        </visual>
        <visual name='base_footprint_fixed_joint_lump__base_link_visual_1'>
          <pose>0 0 0.001 0 0 0</pose>
          <geometry>
            <mesh>
              <scale>1 1 1</scale>
              <uri>file:///home/turtle_on_land/dev_ws/install/landTurtle2/share/landTurtle2/urdf/model://meshes/visual/base_link.STL</uri>
            </mesh>
          </geometry>
          <material>
            <diffuse>1 1 1 1</diffuse>
            <ambient>1 1 1 1</ambient>
          </material>
        </visual>
        <sensor name='imu_sensor' type='imu'>
          <pose>0 0 0 0 0 0</pose>
          <topic>imu</topic>
          <update_rate>1</update_rate>
          <enable_metrics>false</enable_metrics>
          <imu>
            <orientation_reference_frame>
              <localization>CUSTOM</localization>
              <custom_rpy>0 0 0</custom_rpy>
              <grav_dir_x>1 0 0</grav_dir_x>
            </orientation_reference_frame>
            <angular_velocity>
              <x>
                <noise type='none'>
                  <mean>0</mean>
                  <stddev>0</stddev>
                  <bias_mean>0</bias_mean>
                  <bias_stddev>0</bias_stddev>
                  <dynamic_bias_stddev>0</dynamic_bias_stddev>
                  <dynamic_bias_correlation_time>0</dynamic_bias_correlation_time>
                  <precision>0</precision>
                </noise>
              </x>
              <y>
                <noise type='none'>
                  <mean>0</mean>
                  <stddev>0</stddev>
                  <bias_mean>0</bias_mean>
                  <bias_stddev>0</bias_stddev>
                  <dynamic_bias_stddev>0</dynamic_bias_stddev>
                  <dynamic_bias_correlation_time>0</dynamic_bias_correlation_time>
                  <precision>0</precision>
                </noise>
              </y>
              <z>
                <noise type='none'>
                  <mean>0</mean>
                  <stddev>0</stddev>
                  <bias_mean>0</bias_mean>
                  <bias_stddev>0</bias_stddev>
                  <dynamic_bias_stddev>0</dynamic_bias_stddev>
                  <dynamic_bias_correlation_time>0</dynamic_bias_correlation_time>
                  <precision>0</precision>
                </noise>
              </z>
            </angular_velocity>
            <linear_acceleration>
              <x>
                <noise type='none'>
                  <mean>0</mean>
                  <stddev>0</stddev>
                  <bias_mean>0</bias_mean>
                  <bias_stddev>0</bias_stddev>
                  <dynamic_bias_stddev>0</dynamic_bias_stddev>
                  <dynamic_bias_correlation_time>0</dynamic_bias_correlation_time>
                  <precision>0</precision>
                </noise>
              </x>
              <y>
                <noise type='none'>
                  <mean>0</mean>
                  <stddev>0</stddev>
                  <bias_mean>0</bias_mean>
                  <bias_stddev>0</bias_stddev>
                  <dynamic_bias_stddev>0</dynamic_bias_stddev>
                  <dynamic_bias_correlation_time>0</dynamic_bias_correlation_time>
                  <precision>0</precision>
                </noise>
              </y>
              <z>
                <noise type='none'>
                  <mean>0</mean>
                  <stddev>0</stddev>
                  <bias_mean>0</bias_mean>
                  <bias_stddev>0</bias_stddev>
                  <dynamic_bias_stddev>0</dynamic_bias_stddev>
                  <dynamic_bias_correlation_time>0</dynamic_bias_correlation_time>
                  <precision>0</precision>
                </noise>
              </z>
            </linear_acceleration>
            <enable_orientation>true</enable_orientation>
          </imu>
        </sensor>
        <pose>0 0 0 0 0 0</pose>
        <enable_wind>false</enable_wind>
      </link>
      <joint name='Back_left1_joint' type='revolute'>
        <pose>0 -1.3877799999999999e-17 -3.4694499999999997e-18 0 0 0</pose>
        <parent>base_footprint</parent>
        <child>Back_left1</child>
        <axis>
          <xyz>0 0 -1</xyz>
          <limit>
            <lower>-0.78539999999999999</lower>
            <upper>0.78539999999999999</upper>
            <effort>0</effort>
            <velocity>0</velocity>
            <stiffness>100000000</stiffness>
            <dissipation>1</dissipation>
          </limit>
          <dynamics>
            <spring_reference>0</spring_reference>
            <spring_stiffness>0</spring_stiffness>
            <damping>0</damping>
            <friction>0</friction>
          </dynamics>
        </axis>
      </joint>
      <link name='Back_left1'>
        <pose>-0.0837677595780109 0.040083560385204192 0.030000000000086402 8.143668261096543e-28 1.5593164660171008e-29 0.55475997465265081</pose>
        <inertial>
          <pose>-0.0087137312706305498 0.036126297807929503 -0.013052333126020501 0 0 0</pose>
          <mass>0.047100338766454003</mass>
          <inertia>
            <ixx>8.9391808186627097e-06</ixx>
            <ixy>8.3039696331742498e-07</ixy>
            <ixz>-1.32961197398557e-07</ixz>
            <iyy>1.2229960947197099e-05</iyy>
            <iyz>-7.4515785097227404e-07</iyz>
            <izz>1.41319168895854e-05</izz>
          </inertia>
        </inertial>
        <collision name='Back_left1_collision'>
          <pose>0 0 0 0 0 0</pose>
          <geometry>
            <mesh>
              <scale>1 1 1</scale>
              <uri>file:///home/turtle_on_land/dev_ws/install/landTurtle2/share/landTurtle2/urdf/model://meshes/visual/Back_left1.STL</uri>
            </mesh>
          </geometry>
        </collision>
        <visual name='Back_left1_visual'>
          <pose>0 0 0 0 0 0</pose>
          <geometry>
            <mesh>
              <scale>1 1 1</scale>
              <uri>file:///home/turtle_on_land/dev_ws/install/landTurtle2/share/landTurtle2/urdf/model://meshes/visual/Back_left1.STL</uri>
            </mesh>
          </geometry>
          <material>
            <diffuse>1 1 1 1</diffuse>
            <ambient>1 1 1 1</ambient>
          </material>
        </visual>
        <enable_wind>false</enable_wind>
      </link>
      <joint name='Back_left2_joint' type='revolute'>
        <pose>6.9388900000000004e-18 0 6.9388900000000004e-18 0 0 0</pose>
        <parent>Back_left1</parent>
        <child>Back_left2</child>
        <axis>
          <xyz>0 0 1</xyz>
          <limit>
            <lower>-0.26179999999999998</lower>
            <upper>0.26179999999999998</upper>
            <effort>0</effort>
            <velocity>0</velocity>
            <stiffness>100000000</stiffness>
            <dissipation>1</dissipation>
          </limit>
          <dynamics>
            <spring_reference>0</spring_reference>
            <spring_stiffness>0</spring_stiffness>
            <damping>0</damping>
            <friction>0</friction>
          </dynamics>
        </axis>
      </joint>
      <link name='Back_left2'>
        <pose>-0.075439282846325395 0.069429962021468769 -0.0023466257196105289 -0.48558048016051186 0.52330933300497706 1.312937640710464</pose>
        <inertial>
          <pose>-0.0027375091727703501 0.041732656416176302 0.0011541412365935299 0 0 0</pose>
          <mass>0.0099922637471618805</mass>
          <inertia>
            <ixx>4.5950975143612201e-06</ixx>
            <ixy>5.2397089760053902e-07</ixy>
            <ixz>9.0173660961756104e-08</ixz>
            <iyy>1.28722119013764e-06</iyy>
            <iyz>-2.45268383708239e-09</iyz>
            <izz>5.7798974431587599e-06</izz>
          </inertia>
        </inertial>
        <collision name='Back_left2_collision'>
          <pose>0 0 0 0 0 0</pose>
          <geometry>
            <mesh>
              <scale>1 1 1</scale>
              <uri>file:///home/turtle_on_land/dev_ws/install/landTurtle2/share/landTurtle2/urdf/model://meshes/visual/Back_left2.STL</uri>
            </mesh>
          </geometry>
        </collision>
        <visual name='Back_left2_visual'>
          <pose>0 0 0 0 0 0</pose>
          <geometry>
            <mesh>
              <scale>1 1 1</scale>
              <uri>file:///home/turtle_on_land/dev_ws/install/landTurtle2/share/landTurtle2/urdf/model://meshes/visual/Back_left2.STL</uri>
            </mesh>
          </geometry>
          <material>
            <diffuse>0.990196109 1 1 1</diffuse>
            <ambient>0.990196109 1 1 1</ambient>
          </material>
        </visual>
        <enable_wind>false</enable_wind>
      </link>
      <joint name='Back_right1_joint' type='revolute'>
        <pose>0 1.3877799999999999e-17 -3.4694499999999997e-18 0 0 0</pose>
        <parent>base_footprint</parent>
        <child>Back_right1</child>
        <axis>
          <xyz>0 0 -1</xyz>
          <limit>
            <lower>-0.78539999999999999</lower>
            <upper>0.78539999999999999</upper>
            <effort>0</effort>
            <velocity>0</velocity>
            <stiffness>100000000</stiffness>
            <dissipation>1</dissipation>
          </limit>
          <dynamics>
            <spring_reference>0</spring_reference>
            <spring_stiffness>0</spring_stiffness>
            <damping>0</damping>
            <friction>0</friction>
          </dynamics>
        </axis>
      </joint>
      <link name='Back_right1'>
        <pose>-0.0837677595780109 -0.040083560385204192 0.030000000000086402 2.4763014561687976e-27 -2.9023850351099289e-27 -0.55475997465264804</pose>
        <inertial>
          <pose>-0.0087137312756632793 -0.036126756639463298 -0.0130527181254355 0 0 0</pose>
          <mass>0.047100338750227101</mass>
          <inertia>
            <ixx>8.9391808159085007e-06</ixx>
            <ixy>-8.3018404588369301e-07</ixy>
            <ixz>-1.3278254400382199e-07</ixz>
            <iyy>1.2230618455865701e-05</iyy>
            <iyz>7.4504191057743395e-07</iyz>
            <izz>1.4131259370331899e-05</izz>
          </inertia>
        </inertial>
        <collision name='Back_right1_collision'>
          <pose>0 0 0 0 0 0</pose>
          <geometry>
            <mesh>
              <scale>1 1 1</scale>
              <uri>file:///home/turtle_on_land/dev_ws/install/landTurtle2/share/landTurtle2/urdf/model://meshes/visual/Back_right1.STL</uri>
            </mesh>
          </geometry>
        </collision>
        <visual name='Back_right1_visual'>
          <pose>0 0 0 0 0 0</pose>
          <geometry>
            <mesh>
              <scale>1 1 1</scale>
              <uri>file:///home/turtle_on_land/dev_ws/install/landTurtle2/share/landTurtle2/urdf/model://meshes/visual/Back_right1.STL</uri>
            </mesh>
          </geometry>
          <material>
            <diffuse>1 1 1 1</diffuse>
            <ambient>1 1 1 1</ambient>
          </material>
        </visual>
        <enable_wind>false</enable_wind>
      </link>
      <joint name='Back_right2_joint' type='revolute'>
        <pose>1.73472e-17 1.3877799999999999e-17 2.7755599999999997e-17 -1.1796099999999999e-16 -2.7755599999999997e-17 1.6370400000000001e-33</pose>
        <parent>Back_right1</parent>
        <child>Back_right2</child>
        <axis>
          <xyz>-2.775557561562891e-17 1.1796119636642286e-16 1</xyz>
          <limit>
            <lower>-0.26179999999999998</lower>
            <upper>0.26179999999999998</upper>
            <effort>0</effort>
            <velocity>0</velocity>
            <stiffness>100000000</stiffness>
            <dissipation>1</dissipation>
          </limit>
          <dynamics>
            <spring_reference>0</spring_reference>
            <spring_stiffness>0</spring_stiffness>
            <damping>0</damping>
            <friction>0</friction>
          </dynamics>
        </axis>
      </joint>
      <link name='Back_right2'>
        <pose>-0.075439282846325395 -0.069429962021468686 -0.0023466257196105289 0.69813170079772591 0 -0.55475997465264804</pose>
        <inertial>
          <pose>-0.034171137770162299 -0.024117182006824299 0.0011549758748340001 0 0 0</pose>
          <mass>0.0099900976552216702</mass>
          <inertia>
            <ixx>2.08331821365722e-06</ixx>
            <ixy>-1.50841082576915e-06</ixy>
            <ixz>5.8477098025222497e-08</ixz>
            <iyy>3.7995863979891698e-06</iyy>
            <iyz>-6.8514428300258798e-08</iyz>
            <izz>5.7805743959628001e-06</izz>
          </inertia>
        </inertial>
        <collision name='Back_right2_collision'>
          <pose>0 0 0 0 0 0</pose>
          <geometry>
            <mesh>
              <scale>1 1 1</scale>
              <uri>file:///home/turtle_on_land/dev_ws/install/landTurtle2/share/landTurtle2/urdf/model://meshes/visual/Back_right2.STL</uri>
            </mesh>
          </geometry>
        </collision>
        <visual name='Back_right2_visual'>
          <pose>0 0 0 0 0 0</pose>
          <geometry>
            <mesh>
              <scale>1 1 1</scale>
              <uri>file:///home/turtle_on_land/dev_ws/install/landTurtle2/share/landTurtle2/urdf/model://meshes/visual/Back_right2.STL</uri>
            </mesh>
          </geometry>
          <material>
            <diffuse>0.990196109 1 1 1</diffuse>
            <ambient>0.990196109 1 1 1</ambient>
          </material>
        </visual>
        <enable_wind>false</enable_wind>
      </link>
      <joint name='Front_left1_joint' type='revolute'>
        <pose>0 -6.9388900000000004e-18 -3.4694499999999997e-18 0 0 0</pose>
        <parent>base_footprint</parent>
        <child>Front_left1</child>
        <axis>
          <xyz>0 0 -1</xyz>
          <limit>
            <lower>-0.78539999999999999</lower>
            <upper>0.78539999999999999</upper>
            <effort>0</effort>
            <velocity>0</velocity>
            <stiffness>100000000</stiffness>
            <dissipation>1</dissipation>
          </limit>
          <dynamics>
            <spring_reference>0</spring_reference>
            <spring_stiffness>0</spring_stiffness>
            <damping>0</damping>
            <friction>0</friction>
          </dynamics>
        </axis>
      </joint>
      <link name='Front_left1'>
        <pose>0.065905120563841998 0.038460577659128206 0.030000000000086402 8.0831997457424045e-28 -6.3078487131251997e-27 2.9042657168881099</pose>
        <inertial>
          <pose>0.0080805215905642193 -0.044921346212558201 -0.00321271349754684 0 0 0</pose>
          <mass>0.047842202862403801</mass>
          <inertia>
            <ixx>1.07549991380887e-05</ixx>
            <ixy>1.0675385025277901e-06</ixy>
            <ixz>-7.7551710135909995e-08</ixz>
            <iyy>1.15158632373778e-05</iyy>
            <iyz>1.8520008386481499e-06</iyz>
            <izz>1.5396821288555701e-05</izz>
          </inertia>
        </inertial>
        <collision name='Front_left1_collision'>
          <pose>0 0 0 0 0 0</pose>
          <geometry>
            <mesh>
              <scale>1 1 1</scale>
              <uri>file:///home/turtle_on_land/dev_ws/install/landTurtle2/share/landTurtle2/urdf/model://meshes/visual/Front_left1.STL</uri>
            </mesh>
          </geometry>
        </collision>
        <visual name='Front_left1_visual'>
          <pose>0 0 0 0 0 0</pose>
          <geometry>
            <mesh>
              <scale>1 1 1</scale>
              <uri>file:///home/turtle_on_land/dev_ws/install/landTurtle2/share/landTurtle2/urdf/model://meshes/visual/Front_left1.STL</uri>
            </mesh>
          </geometry>
          <material>
            <diffuse>1 1 1 1</diffuse>
            <ambient>1 1 1 1</ambient>
          </material>
        </visual>
        <enable_wind>false</enable_wind>
      </link>
      <joint name='Front_left2_joint' type='revolute'>
        <pose>2.7755599999999997e-17 1.3877799999999999e-17 0 0 1.3877799999999999e-17 0</pose>
        <parent>Front_left1</parent>
        <child>Front_left2</child>
        <axis>
          <xyz>1.3877787807814457e-17 0 1</xyz>
          <limit>
            <lower>-0.26179999999999998</lower>
            <upper>0.26179999999999998</upper>
            <effort>0</effort>
            <velocity>0</velocity>
            <stiffness>100000000</stiffness>
            <dissipation>1</dissipation>
          </limit>
          <dynamics>
            <spring_reference>0</spring_reference>
            <spring_stiffness>0</spring_stiffness>
            <damping>0</damping>
            <friction>0</friction>
          </dynamics>
        </axis>
      </joint>
      <link name='Front_left2'>
        <pose>0.075792923795433023 0.079338625810797245 0.0096262831171998187 0.69813170079774112 -1.5265566588595902e-16 2.9042657168881103</pose>
        <inertial>
          <pose>0.0210209202048704 -0.021840406154329299 -0.0074163348118039003 0 0 0</pose>
          <mass>0.028369475308161699</mass>
          <inertia>
            <ixx>8.5444443168283992e-06</ixx>
            <ixy>6.3074853217134099e-06</ixy>
            <ixz>-1.9784274710968501e-07</ixz>
            <iyy>2.4952474398110999e-05</iyy>
            <iyz>-4.9486168600064401e-07</iyz>
            <izz>3.2865597918900499e-05</izz>
          </inertia>
        </inertial>
        <collision name='Front_left2_collision'>
          <pose>0 0 0 0 0 0</pose>
          <geometry>
            <mesh>
              <scale>1 1 1</scale>
              <uri>file:///home/turtle_on_land/dev_ws/install/landTurtle2/share/landTurtle2/urdf/model://meshes/visual/Front_left2.STL</uri>
            </mesh>
          </geometry>
        </collision>
        <visual name='Front_left2_visual'>
          <pose>0 0 0 0 0 0</pose>
          <geometry>
            <mesh>
              <scale>1 1 1</scale>
              <uri>file:///home/turtle_on_land/dev_ws/install/landTurtle2/share/landTurtle2/urdf/model://meshes/visual/Front_left2.STL</uri>
            </mesh>
          </geometry>
          <material>
            <diffuse>1 1 1 1</diffuse>
            <ambient>1 1 1 1</ambient>
          </material>
        </visual>
        <enable_wind>false</enable_wind>
      </link>
      <joint name='Front_right1_joint' type='revolute'>
        <pose>0 6.9388900000000004e-18 -3.4694499999999997e-18 0 0 0</pose>
        <parent>base_footprint</parent>
        <child>Front_right1</child>
        <axis>
          <xyz>0 0 -1</xyz>
          <limit>
            <lower>-0.78539999999999999</lower>
            <upper>0.78539999999999999</upper>
            <effort>0</effort>
            <velocity>0</velocity>
            <stiffness>100000000</stiffness>
            <dissipation>1</dissipation>
          </limit>
          <dynamics>
            <spring_reference>0</spring_reference>
            <spring_stiffness>0</spring_stiffness>
            <damping>0</damping>
            <friction>0</friction>
          </dynamics>
        </axis>
      </joint>
      <link name='Front_right1'>
        <pose>0.065905120563841998 -0.038460577659128102 0.030000000000086402 -3.3915849700989313e-28 -3.3171306847729348e-27 -2.9042657168881099</pose>
        <inertial>
          <pose>0.0080805216296491698 0.044921797963332399 -0.0032130925271061099 0 0 0</pose>
          <mass>0.047842202721792799</mass>
          <inertia>
            <ixx>1.07549991205532e-05</ixx>
            <ixy>-1.06732554744789e-06</ixy>
            <ixz>-7.7730357900511994e-08</ixz>
            <iyy>1.15165207395343e-05</iyy>
            <iyz>-1.8518848739368101e-06</iyz>
            <izz>1.5396163705799201e-05</izz>
          </inertia>
        </inertial>
        <collision name='Front_right1_collision'>
          <pose>0 0 0 0 0 0</pose>
          <geometry>
            <mesh>
              <scale>1 1 1</scale>
              <uri>file:///home/turtle_on_land/dev_ws/install/landTurtle2/share/landTurtle2/urdf/model://meshes/visual/Front_right1.STL</uri>
            </mesh>
          </geometry>
        </collision>
        <visual name='Front_right1_visual'>
          <pose>0 0 0 0 0 0</pose>
          <geometry>
            <mesh>
              <scale>1 1 1</scale>
              <uri>file:///home/turtle_on_land/dev_ws/install/landTurtle2/share/landTurtle2/urdf/model://meshes/visual/Front_right1.STL</uri>
            </mesh>
          </geometry>
          <material>
            <diffuse>0.990196109 1 1 1</diffuse>
            <ambient>0.990196109 1 1 1</ambient>
          </material>
        </visual>
        <enable_wind>false</enable_wind>
      </link>
      <joint name='Front_right2_joint' type='revolute'>
        <pose>-1.3877799999999999e-17 0 1.3877799999999999e-17 0 0 2.7755599999999997e-17</pose>
        <parent>Front_right1</parent>
        <child>Front_right2</child>
        <axis>
          <xyz>0 0 1</xyz>
          <limit>
            <lower>-0.26179999999999998</lower>
            <upper>0.26179999999999998</upper>
            <effort>0</effort>
            <velocity>0</velocity>
            <stiffness>100000000</stiffness>
            <dissipation>1</dissipation>
          </limit>
          <dynamics>
            <spring_reference>0</spring_reference>
            <spring_stiffness>0</spring_stiffness>
            <damping>0</damping>
            <friction>0</friction>
          </dynamics>
        </axis>
      </joint>
      <link name='Front_right2'>
        <pose>0.075792923795432982 -0.07933862581079705 0.0096262831171998187 0.69813170079774123 2.7755575615628914e-17 0.23732693670168015</pose>
        <inertial>
          <pose>-0.021021848093744001 -0.0218401305507092 -0.0074162388037017904 0 0 0</pose>
          <mass>0.028367563421984099</mass>
          <inertia>
            <ixx>8.5434060144301498e-06</ixx>
            <ixy>-6.3080716742018701e-06</ixy>
            <ixz>1.97748599968732e-07</ixz>
            <iyy>2.4952663130849299e-05</iyy>
            <iyz>-4.9472797372267998e-07</iyz>
            <izz>3.2864805298720803e-05</izz>
          </inertia>
        </inertial>
        <collision name='Front_right2_collision'>
          <pose>0 0 0 0 0 0</pose>
          <geometry>
            <mesh>
              <scale>1 1 1</scale>
              <uri>file:///home/turtle_on_land/dev_ws/install/landTurtle2/share/landTurtle2/urdf/model://meshes/visual/Front_right2.STL</uri>
            </mesh>
          </geometry>
        </collision>
        <visual name='Front_right2_visual'>
          <pose>0 0 0 0 0 0</pose>
          <geometry>
            <mesh>
              <scale>1 1 1</scale>
              <uri>file:///home/turtle_on_land/dev_ws/install/landTurtle2/share/landTurtle2/urdf/model://meshes/visual/Front_right2.STL</uri>
            </mesh>
          </geometry>
          <material>
            <diffuse>0.990196109 1 1 1</diffuse>
            <ambient>0.990196109 1 1 1</ambient>
          </material>
        </visual>
        <enable_wind>false</enable_wind>
      </link>
      <joint name='Sensor' type='fixed'>
        <pose>0 -2.7105099999999998e-20 -8.6736199999999997e-19 0 0 0</pose>
        <parent>base_footprint</parent>
        <child>Sensor_l1</child>
      </joint>
      <link name='Sensor_l1'>
        <pose>0.097500000000000003 -4.0389678347315804e-28 0.0059999999999718057 -4.8830091761337011e-31 1.5464109681191901e-31 0.00080000008533324376</pose>
        <sensor name='gpu_lidar' type='gpu_lidar'>
          <pose>0 -2.7105099999999998e-20 -8.6736199999999997e-19 0 0 0</pose>
          <topic>lidar</topic>
          <update_rate>10</update_rate>
          <enable_metrics>false</enable_metrics>
          <lidar>
            <scan>
              <horizontal>
                <samples>640</samples>
                <resolution>1</resolution>
                <min_angle>-1.396263</min_angle>
                <max_angle>1.396263</max_angle>
              </horizontal>
              <vertical>
                <samples>1</samples>
                <min_angle>0</min_angle>
                <max_angle>0</max_angle>
                <resolution>0.01</resolution>
              </vertical>
            </scan>
            <range>
              <min>0.080000000000000002</min>
              <max>100</max>
              <resolution>0.01</resolution>
            </range>
            <noise>
              <type>none</type>
              <mean>0</mean>
              <stddev>0</stddev>
            </noise>
            <visibility_mask>4294967295</visibility_mask>
          </lidar>
        </sensor>
        <sensor name='boundingbox_camera' type='boundingbox_camera'>
          <topic>camera1</topic>
          <camera>
            <horizontal_fov>1.0469999999999999</horizontal_fov>
            <image>
              <width>800</width>
              <height>600</height>
            </image>
            <clip>
              <near>0.10000000000000001</near>
              <far>10</far>
            </clip>
          </camera>
          <always_on>true</always_on>
          <update_rate>30</update_rate>
          <visualize>true</visualize>
        </sensor>
        <inertial>
          <pose>0 0 0 0 0 0</pose>
          <mass>1</mass>
          <inertia>
            <ixx>1</ixx>
            <ixy>0</ixy>
            <ixz>0</ixz>
            <iyy>1</iyy>
            <iyz>0</iyz>
            <izz>1</izz>
          </inertia>
        </inertial>
        <enable_wind>false</enable_wind>
      </link>
      <frame name='sensor' attached_to='base_link'>
        <pose>0.097500000000000003 0 0.0050000000000000001 0 0 1.5708</pose>
      </frame>
      <frame name='Sensor_link' attached_to='sensor'>
        <pose>0 0 0 0 0 -1.5700000000000001</pose>
      </frame>
      <frame name='base_footprint_joint' attached_to='base_footprint'>
        <pose>0 0 0.001 0 0 0</pose>
      </frame>
      <frame name='base_link' attached_to='base_footprint_joint'>
        <pose>0 0 0 0 0 0</pose>
      </frame>
      <plugin name='ignition::gazebo::systems::JointStatePublisher' filename='ignition-gazebo-joint-state-publisher-system'/>
      <plugin name='ignition::gazebo::systems::PosePublisher' filename='ignition-gazebo-pose-publisher-system'>
        <publish_link_pose>true</publish_link_pose>
        <use_pose_vector_msg>true</use_pose_vector_msg>
      </plugin>
      <pose>9.1411265104273557e-14 -6.2964051821170993e-16 -617.04855099993199 4.0642268702623001e-15 -1.8271276856730142e-11 9.5210978298122965e-17</pose>
      <static>false</static>
      <self_collide>false</self_collide>
    </model>
  </world>
</sdf>
