<?xml version="1.0" encoding="utf-8"?>
<!-- Turtle on land URDF file-->
<robot name="URDF1" xmlns:xacro="http://www.ros.org/wiki/xacro">

 <!--Link1; Turtle Shell bottom-->
 <link name="base_footprint">
 <!--Visual description of link-->
     <visual>
     <!--Description of origin rotational and position coordinates -->
         <origin xyz="0 0 0" rpy="0 0 0" />
         <geometry>
         <!--Modeled as a box of dimensions; Length, width, height-->
             <box size="0.001 0.001 0.001" />
         </geometry>
     </visual>
 </link>
 <!--Link parameteres are repeated for each link-->

 <!--ros gazebo plugin-->


 <frame name="lidar_frame" attached_to='base_footprint'>
    <pose>0.8 0 0.5 0 0 0</pose>
 </frame>

 <plugin
      filename="gz-sim-sensors-system"
      name="gz::sim::systems::Sensors">
      <render_engine>ogre2</render_engine>
    </plugin>

  <sensor name='gpu_lidar' type='gpu_lidar'>"
    <pose relative_to='lidar_frame'>0 0 0 0 0 0</pose>
    <topic>lidar</topic>
    <update_rate>10</update_rate>
    <ray>
        <scan>
            <horizontal>
                <samples>640</samples>
                <resolution>1</resolution>
                <min_angle>-1.396263</min_angle>
                <max_angle>1.396263</max_angle>
            </horizontal>
            <vertical>
                <samples>1</samples>
                <resolution>0.01</resolution>
                <min_angle>0</min_angle>
                <max_angle>0</max_angle>
            </vertical>
        </scan>
        <range>
            <min>0.08</min>
            <max>10.0</max>
            <resolution>0.01</resolution>
        </range>
    </ray>
    <always_on>1</always_on>
    <visualize>true</visualize>
  </sensor>

 <!--Joint1; fixed joint between Link1 and 2 -->
 <!--Describes movement of the joint in relation to the two links , fixed, revolute and rotational -->
 <joint name="base_footprint_joint" type="fixed">
  <!--Description of joint origin rotational and position coordinates-->
     <origin xyz="0 0 0.001" rpy="0 0 0" />
     <!--Parent link defining parent frame-->
     <parent link="base_footprint"/>
     <!--Child link defining child frame-->
     <child link="base_link" />
  </joint>
  <!--Joint parameters are the same throughout for each link connection-->

 <!--Link2;Turtle Shell Top-->
   <link
    name="base_link">
    <!--Interial properties-->
    <inertial>
      <origin
        xyz="-0.0076873 -3.8825E-05 -0.0022692"
        rpy="0 0 0" />
        <!--Mass parameter for link-->
      <mass
        value="0.37301" />
        <!--Inertial properties-->
      <inertia
        ixx="0.00031924"
        ixy="2.9938E-07"
        ixz="-1.8594E-05"
        iyy="0.00078244"
        iyz="4.8628E-08"
        izz="0.0010267" />
    </inertial>
    <!--Origin description-->
    <visual>
      <origin
        xyz="0 0 0"
        rpy="0 0 0" />
        <!--Filepath to STL visual Mesh file-->
      <geometry>
        <mesh
          filename="package://meshes/visual/base_link.STL" />
      </geometry>
      <material
        name="">
        <!--Link Color-->
        <color 
          rgba="0 1 0 1" />
      </material>
    </visual>
    <!--Collision parameter for Link-->
    <collision>
      <origin
        xyz="0 0 0"
        rpy="0 0 0" />
        <!--Filepath to STL visual Mesh file-->
      <geometry>
        <mesh
          filename="package://meshes/visual/base_link.STL" />
      </geometry>
    </collision>
  </link>

  <!--Link3; Front right shoulder-->
  <link
    name="Front_right1">
    <!--Interial properties of Link3-->
    <inertial>
      <origin
        xyz="0.0080805 0.044922 -0.0032131"
        rpy="0 0 0" />
        <!--Mass Parameter of Link3-->
      <mass
        value="0.047842" />
      <inertia
        ixx="1.0755E-05"
        ixy="-1.0673E-06"
        ixz="-7.773E-08"
        iyy="1.1517E-05"
        iyz="-1.8519E-06"
        izz="1.5396E-05" />
    </inertial>
    <visual>
      <origin
        xyz="0 0 0"
        rpy="0 0 0" />
      <geometry>
        <mesh
          filename="package://meshes/visual/Front_right1.STL" />
      </geometry>
      <material
        name="">
        <color
          rgba="0 1 0 1" />
      </material>
    </visual>
    <collision>
      <origin
        xyz="0 0 0"
        rpy="0 0 0" />
      <geometry>
        <mesh
          filename="package://meshes/visual/Front_right1.STL" />
      </geometry>
    </collision>
  </link>

  <!--Joint2;Revolute joint between base link and link3-->
  <joint
    name="Front_right1_joint"
    type="revolute">
    <origin
      xyz="0.065905 -0.038461 0.029"
      rpy="0 0 -2.1584" />
    <parent
      link="base_link" />
    <child
      link="Front_right1" />
    <axis
      xyz="0 0 -1" />
    <limit
      lower="-0.7854"
      upper="0.7854"
      effort="0"
      velocity="1"/>
  </joint>

  <!--Link4; Froint right flipper-->
  <link
    name="Front_right2">
    <inertial>
      <origin
        xyz="-0.018453 -0.024053 -0.0074149"
        rpy="0 0 0" />
      <mass
        value="0.028365" />
      <inertia
        ixx="1.015E-05"
        ixy="-7.9763E-06"
        ixz="2.5126E-07"
        iyy="2.3351E-05"
        iyz="-4.6909E-07"
        izz="3.2871E-05" />
    </inertial>
    <visual>
      <origin
        xyz="0 0 0"
        rpy="0 0 0" />
      <geometry>
        <mesh
          filename="package://meshes/visual/Front_right2.STL" />
      </geometry>
      <material
        name="">
        <color
          rgba="0 1 0 1" />
      </material>
    </visual>
    <collision>
      <origin
        xyz="0 0 0"
        rpy="0 0 0" />
      <geometry>
        <mesh
          filename="package://meshes/visual/Front_right2.STL" />
      </geometry>
    </collision>
  </link>

  <!--Joint 3; revolute joint between Link3 and 4-->
  <joint
    name="Front_right2_joint"
    type="revolute">
    <origin
      xyz="0 0.042057 -0.020374"
      rpy="0.69813 0 3.1416" />
    <parent
      link="Front_right1" />
    <child
      link="Front_right2" />
    <axis
      xyz="0 0 1" />
    <limit
      lower="-0.2618"
      upper="0.2618"
      effort="0"
      velocity="0" />
  </joint>

  <!--Link5; Back right shoulder-->
  <link
    name="Back_right1">
    <inertial>
      <origin
        xyz="-0.0087137 -0.036127 -0.013053"
        rpy="0 0 0" />
      <mass
        value="0.0471" />
      <inertia
        ixx="8.9392E-06"
        ixy="-8.3018E-07"
        ixz="-1.3278E-07"
        iyy="1.2231E-05"
        iyz="7.4504E-07"
        izz="1.4131E-05" />
    </inertial>
    <visual>
      <origin
        xyz="0 0 0"
        rpy="0 0 0" />
      <geometry>
        <mesh
          filename="package://meshes/visual/Back_right1.STL" />
      </geometry>
      <material
        name="">
        <color
          rgba="0 1 0 1" />
      </material>
    </visual>
    <collision>
      <origin
        xyz="0 0 0"
        rpy="0 0 0" />
      <geometry>
        <mesh
          filename="package://meshes/visual/Back_right1.STL" />
      </geometry>
    </collision>
  </link>

  <!--Joint4; revolute joint between base Link and Link5-->
  <joint
    name="Back_right1_joint"
    type="revolute">
    <origin
      xyz="-0.083768 -0.040084 0.029"
      rpy="0 0 -0.24199" />
    <parent
      link="base_link" />
    <child
      link="Back_right1" />
    <axis
      xyz="0 0 -1" />
    <limit
      lower="-0.7854"
      upper="0.7854"
      effort="0"
      velocity="0" />
  </joint>

  <!--Link6; Back right flipper-->
  <link
    name="Back_right2">
    <inertial>
      <origin
        xyz="-0.013023 -0.015316 -0.0052397"
        rpy="0 0 0" />
      <mass
        value="0.0099911" />
      <inertia
        ixx="1.8331E-06"
        ixy="-1.3351E-06"
        ixz="5.2365E-08"
        iyy="4.0494E-06"
        iyz="-7.3412E-08"
        izz="5.7801E-06" />
    </inertial>
    <visual>
      <origin
        xyz="0 0 0"
        rpy="0 0 0" />
      <geometry>
        <mesh
          filename="package://meshes/visual/Back_right2.STL" />
      </geometry>
      <material
        name="">
        <color
          rgba="0 1 0 1" />
      </material>
    </visual>
    <collision>
      <origin
        xyz="0 0 0"
        rpy="0 0 0" />
      <geometry>
        <mesh
          filename="package://meshes/visual/Back_right2.STL" />
      </geometry>
    </collision>
  </link>

  <!--Joint5; revolute joint between Link 5 and 6-->
  <joint
    name="Back_right2_joint"
    type="revolute">
    <origin
      xyz="0 -0.030582 -0.032411"
      rpy="0.69813 0 0" />
    <parent
      link="Back_right1" />
    <child
      link="Back_right2" />
    <axis
      xyz="0 0 1" />
    <limit
      lower="-0.2618"
      upper="0.2618"
      effort="0"
      velocity="0" />
  </joint>

  <!--Link7; Front left shoulder-->
  <link
    name="Front_left1">
    <inertial>
      <origin
        xyz="0.0080805 -0.044921 -0.0032127"
        rpy="0 0 0" />
      <mass
        value="0.047842" />
      <inertia
        ixx="1.0755E-05"
        ixy="1.0675E-06"
        ixz="-7.7552E-08"
        iyy="1.1516E-05"
        iyz="1.852E-06"
        izz="1.5397E-05" />
    </inertial>
    <visual>
      <origin
        xyz="0 0 0"
        rpy="0 0 0" />
      <geometry>
        <mesh
          filename="package://meshes/visual/Front_left1.STL" />
      </geometry>
      <material
        name="">
        <color
          rgba="0 1 0 1" />
      </material>
    </visual>
    <collision>
      <origin
        xyz="0 0 0"
        rpy="0 0 0" />
      <geometry>
        <mesh
          filename="package://meshes/visual/Front_left1.STL" />
      </geometry>
    </collision>
  </link>

  <!--Joint6; revolute joint between base link and link 7-->
  <joint
    name="Front_left1_joint"
    type="revolute">
    <origin
      xyz="0.065905 0.038461 0.029"
      rpy="0 0 2.1584" />
    <parent
      link="base_link" />
    <child
      link="Front_left1" />
    <axis
      xyz="0 0 -1" />
    <limit
      lower="-0.7854"
      upper="0.7854"
      effort="0"
      velocity="0" />
  </joint>

  <!--Link8; Front left flipper-->
  <link
    name="Front_left2">
    <inertial>
      <origin
        xyz="0.018449 -0.024055 -0.0074161"
        rpy="0 0 0" />
      <mass
        value="0.028369" />
      <inertia
        ixx="1.0151E-05"
        ixy="7.9738E-06"
        ixz="-2.5212E-07"
        iyy="2.3348E-05"
        iyz="-4.6947E-07"
        izz="3.2868E-05" />
    </inertial>
    <visual>
      <origin
        xyz="0 0 0"
        rpy="0 0 0" />
      <geometry>
        <mesh
          filename="package://meshes/visual/Front_left2.STL" />
      </geometry>
      <material
        name="">
        <color
          rgba="0 1 0 1" />
      </material>
    </visual>e
    <collision>
      <origin
        xyz="0 0 0"
        rpy="0 0 0" />
      <geometry>
        <mesh
          filename="package://meshes/visual/Front_left2.STL" />
      </geometry>
    </collision>
  </link>

  <!--Joint7; revolute joint between Link 7 and 8-->
  <joint
    name="Front_left2_joint"
    type="revolute">
    <origin
      xyz="0 -0.042057 -0.020374"
      rpy="0.69813 0 0" />
    <parent
      link="Front_left1" />
    <child
      link="Front_left2" />
    <axis
      xyz="0 0 1" />
    <limit
      lower="-0.2618"
      upper="0.2618"
      effort="0"
      velocity="0" />
  </joint>

  <!--Link9; Back left shoulder-->
  <link
    name="Back_left1">
    <inertial>
      <origin
        xyz="-0.0087137 0.036126 -0.013052"
        rpy="0 0 0" />
      <mass
        value="0.0471" />
      <inertia
        ixx="8.9392E-06"
        ixy="8.304E-07"
        ixz="-1.3296E-07"
        iyy="1.223E-05"
        iyz="-7.4516E-07"
        izz="1.4132E-05" />
    </inertial>
    <visual>
      <origin
        xyz="0 0 0"
        rpy="0 0 0" />
      <geometry>
        <mesh
          filename="package://meshes/visual/Back_left1.STL" />
      </geometry>
      <material
        name="">
        <color
          rgba="0 1 0 1" />
      </material>
    </visual>
    <collision>
      <origin
        xyz="0 0 0"
        rpy="0 0 0" />
      <geometry>
        <mesh
          filename="package://meshes/visual/Back_left1.STL" />
      </geometry>
    </collision>
  </link>

  <!--Joint8 revolute joint between base link and link 9-->
  <joint
    name="Back_left1_joint"
    type="revolute">
    <origin
      xyz="-0.083768 0.040084 0.029"
      rpy="0 0 0.24199" />
    <parent
      link="base_link" />
    <child
      link="Back_left1" />
    <axis
      xyz="0 0 -1" />
    <limit
      lower="-0.7854"
      upper="0.7854"
      effort="0"
      velocity="0" />
  </joint>

  <!--Link10;Back left flipper-->
  <link
    name="Back_left2">
    <inertial>
      <origin
        xyz="0.010585 0.017092 -0.0052398"
        rpy="0 0 0" />
      <mass
        value="0.0099917" />
      <inertia
        ixx="4.6202E-06"
        ixy="-4.3699E-07"
        ixz="8.5959E-08"
        iyy="1.2622E-06"
        iyz="-2.7328E-08"
        izz="5.78E-06" />
    </inertial>
    <visual>
      <origin
        xyz="0 0 0"
        rpy="0 0 0" />
      <geometry>
        <mesh
          filename="package://meshes/visual/Back_left2.STL" />
      </geometry>
      <material
        name="">
        <color
          rgba="0 1 0 1" />
      </material>
    </visual>
    <collision>
      <origin
        xyz="0 0 0"
        rpy="0 0 0" />
      <geometry>
        <mesh
          filename="package://meshes/visual/Back_left2.STL" />
      </geometry>
    </collision>
  </link>

  <!--Joint9; revolute joint betwen Link 9 and 10-->
  <joint
    name="Back_left2_joint"
    type="revolute">
    <origin
      xyz="0 0.030582 -0.032411"
      rpy="-0.25187 0.65835 1.1726" />
    <parent
      link="Back_left1" />
    <child
      link="Back_left2" />
    <axis
      xyz="0 0 1" />
    <limit
      lower="-0.2618"
      upper="0.2618"
      effort="0"
      velocity="0" />
  </joint>
  
  <link name="ultrasonic_sensor_link" />

  <joint name="ultrasonic_sensor_joint" type="fixed">
    <parent link="base_link"/>
    <child link="ultrasonic_sensor_link"/>
    <origin xyz="0.07 0.0 0.076" rpy="0 0 0"/>
  </joint>
  
  <gazebo reference="ultrasonic_sensor_link">
    <sensor type="ray" name="ultrasonic_sensor">
      <pose>0 0 0 0 0 0</pose>
      <!-- 是否可视化，gazebo里能不能看到 -->
      <visualize>true</visualize>
      <!-- 扫描速率，也就是数据更新速率 -->
      <update_rate>5</update_rate>
      <ray>
        <scan>
          <!-- 水平扫描的点数 -->
          <horizontal>
            <samples>5</samples>
            <resolution>1</resolution>
            <min_angle>-0.12</min_angle>
            <max_angle>0.12</max_angle>
          </horizontal>
          <!-- 垂直方向扫描的点数 -->
          <vertical>
            <samples>5</samples>
            <resolution>1</resolution>
            <min_angle>-0.01</min_angle>
            <max_angle>0.01</max_angle>
          </vertical>
        </scan>
        <!-- 超声波检测的范围和数据分辨率单位m -->
        <range>
          <min>0.02</min>
          <max>4</max>
          <resolution>0.01</resolution>
        </range>
        <!-- 数据噪声采用高斯噪声 -->
        <noise>
          <type>gaussian</type>
          <mean>0.0</mean>
          <stddev>0.01</stddev>
        </noise>
      </ray>
      <plugin name="ultrasonic_sensor_controller" filename="libgazebo_ros_ray_sensor.so">
        <ros>
          <!-- 重映射输出的话题名称 -->
          <remapping>~/out:=ultrasonic_sensor_1</remapping>
        </ros>
        <!-- 输出消息的类型，注意与雷达区分，这里是sensor_msgs/Range -->
        <output_type>sensor_msgs/Range</output_type>
        <!-- 射线类型，这里要写ultrasound，注意和雷达区分 -->
        <radiation_type>ultrasound</radiation_type>
        <!-- frame名称，填写link名称即可 -->
        <frame_name>ultrasonic_sensor_link</frame_name>
      </plugin>
    </sensor>
  </gazebo>

   <!-- Import diffbot ros2_control description -->
  <xacro:include filename="$(find turtle_on_land_demo)/config/ros2_control.xacro" />
</robot>
